ERROR 2022-07-13 20:34:16,612 Internal Server Error: /news/ C:\Program Files\Python\Python310\lib\site-packages\django\utils\log.py (<class 'django.db.utils.OperationalError'>, OperationalError('no such column: news_post.title_en_us'), <traceback object at 0x00000263CB45BD40>)
Traceback (most recent call last):
  File "C:\Program Files\Python\Python310\lib\site-packages\django\db\backends\utils.py", line 89, in _execute
    return self.cursor.execute(sql, params)
  File "C:\Program Files\Python\Python310\lib\site-packages\django\db\backends\sqlite3\base.py", line 477, in execute
    return Database.Cursor.execute(self, query, params)
sqlite3.OperationalError: no such column: news_post.title_en_us

The above exception was the direct cause of the following exception:

Traceback (most recent call last):
  File "C:\Program Files\Python\Python310\lib\site-packages\django\core\handlers\exception.py", line 55, in inner
    response = get_response(request)
  File "C:\Program Files\Python\Python310\lib\site-packages\django\core\handlers\base.py", line 220, in _get_response
    response = response.render()
  File "C:\Program Files\Python\Python310\lib\site-packages\django\template\response.py", line 114, in render
    self.content = self.rendered_content
  File "C:\Program Files\Python\Python310\lib\site-packages\django\template\response.py", line 92, in rendered_content
    return template.render(context, self._request)
  File "C:\Program Files\Python\Python310\lib\site-packages\django\template\backends\django.py", line 62, in render
    return self.template.render(context)
  File "C:\Program Files\Python\Python310\lib\site-packages\django\template\base.py", line 175, in render
    return self._render(context)
  File "C:\Program Files\Python\Python310\lib\site-packages\django\template\base.py", line 167, in _render
    return self.nodelist.render(context)
  File "C:\Program Files\Python\Python310\lib\site-packages\django\template\base.py", line 1000, in render
    return SafeString("".join([node.render_annotated(context) for node in self]))
  File "C:\Program Files\Python\Python310\lib\site-packages\django\template\base.py", line 1000, in <listcomp>
    return SafeString("".join([node.render_annotated(context) for node in self]))
  File "C:\Program Files\Python\Python310\lib\site-packages\django\template\base.py", line 958, in render_annotated
    return self.render(context)
  File "C:\Program Files\Python\Python310\lib\site-packages\django\template\loader_tags.py", line 157, in render
    return compiled_parent._render(context)
  File "C:\Program Files\Python\Python310\lib\site-packages\django\template\base.py", line 167, in _render
    return self.nodelist.render(context)
  File "C:\Program Files\Python\Python310\lib\site-packages\django\template\base.py", line 1000, in render
    return SafeString("".join([node.render_annotated(context) for node in self]))
  File "C:\Program Files\Python\Python310\lib\site-packages\django\template\base.py", line 1000, in <listcomp>
    return SafeString("".join([node.render_annotated(context) for node in self]))
  File "C:\Program Files\Python\Python310\lib\site-packages\django\template\base.py", line 958, in render_annotated
    return self.render(context)
  File "C:\Program Files\Python\Python310\lib\site-packages\django\template\loader_tags.py", line 63, in render
    result = block.nodelist.render(context)
  File "C:\Program Files\Python\Python310\lib\site-packages\django\template\base.py", line 1000, in render
    return SafeString("".join([node.render_annotated(context) for node in self]))
  File "C:\Program Files\Python\Python310\lib\site-packages\django\template\base.py", line 1000, in <listcomp>
    return SafeString("".join([node.render_annotated(context) for node in self]))
  File "C:\Program Files\Python\Python310\lib\site-packages\django\template\base.py", line 958, in render_annotated
    return self.render(context)
  File "C:\Program Files\Python\Python310\lib\site-packages\django\template\defaulttags.py", line 321, in render
    if match:
  File "C:\Program Files\Python\Python310\lib\site-packages\django\db\models\query.py", line 324, in __bool__
    self._fetch_all()
  File "C:\Program Files\Python\Python310\lib\site-packages\django\db\models\query.py", line 1507, in _fetch_all
    self._result_cache = list(self._iterable_class(self))
  File "C:\Program Files\Python\Python310\lib\site-packages\django\db\models\query.py", line 57, in __iter__
    results = compiler.execute_sql(
  File "C:\Program Files\Python\Python310\lib\site-packages\django\db\models\sql\compiler.py", line 1361, in execute_sql
    cursor.execute(sql, params)
  File "C:\Program Files\Python\Python310\lib\site-packages\django\db\backends\utils.py", line 103, in execute
    return super().execute(sql, params)
  File "C:\Program Files\Python\Python310\lib\site-packages\django\db\backends\utils.py", line 67, in execute
    return self._execute_with_wrappers(
  File "C:\Program Files\Python\Python310\lib\site-packages\django\db\backends\utils.py", line 80, in _execute_with_wrappers
    return executor(sql, params, many, context)
  File "C:\Program Files\Python\Python310\lib\site-packages\django\db\backends\utils.py", line 84, in _execute
    with self.db.wrap_database_errors:
  File "C:\Program Files\Python\Python310\lib\site-packages\django\db\utils.py", line 91, in __exit__
    raise dj_exc_value.with_traceback(traceback) from exc_value
  File "C:\Program Files\Python\Python310\lib\site-packages\django\db\backends\utils.py", line 89, in _execute
    return self.cursor.execute(sql, params)
  File "C:\Program Files\Python\Python310\lib\site-packages\django\db\backends\sqlite3\base.py", line 477, in execute
    return Database.Cursor.execute(self, query, params)
django.db.utils.OperationalError: no such column: news_post.title_en_us
ERROR 2022-07-13 20:34:16,616 "GET /news/ HTTP/1.1" 500 208659 C:\Program Files\Python\Python310\lib\site-packages\django\core\servers\basehttp.py None
ERROR 2022-07-13 20:34:46,100 Internal Server Error: /news/12 C:\Program Files\Python\Python310\lib\site-packages\django\utils\log.py (<class 'django.db.utils.OperationalError'>, OperationalError('no such column: news_post.title_en_us'), <traceback object at 0x00000263CB21E840>)
Traceback (most recent call last):
  File "C:\Program Files\Python\Python310\lib\site-packages\django\db\backends\utils.py", line 89, in _execute
    return self.cursor.execute(sql, params)
  File "C:\Program Files\Python\Python310\lib\site-packages\django\db\backends\sqlite3\base.py", line 477, in execute
    return Database.Cursor.execute(self, query, params)
sqlite3.OperationalError: no such column: news_post.title_en_us

The above exception was the direct cause of the following exception:

Traceback (most recent call last):
  File "C:\Program Files\Python\Python310\lib\site-packages\django\core\handlers\exception.py", line 55, in inner
    response = get_response(request)
  File "C:\Program Files\Python\Python310\lib\site-packages\django\core\handlers\base.py", line 197, in _get_response
    response = wrapped_callback(request, *callback_args, **callback_kwargs)
  File "C:\Program Files\Python\Python310\lib\site-packages\django\utils\decorators.py", line 133, in _wrapped_view
    response = view_func(request, *args, **kwargs)
  File "C:\Program Files\Python\Python310\lib\site-packages\django\views\generic\base.py", line 84, in view
    return self.dispatch(request, *args, **kwargs)
  File "C:\Program Files\Python\Python310\lib\site-packages\django\views\generic\base.py", line 119, in dispatch
    return handler(request, *args, **kwargs)
  File "C:\Program Files\Python\Python310\lib\site-packages\django\views\generic\detail.py", line 108, in get
    self.object = self.get_object()
  File "E:\Œ¡”◊≈Õ»≈ œ–Œ√–¿ÃÃ»–Œ¬¿Õ»ﬁ\roman7586\pythonProject\Dtotal\newspaper\news\views.py", line 68, in get_object
    obj = super().get_object(queryset=self.queryset)
  File "C:\Program Files\Python\Python310\lib\site-packages\django\views\generic\detail.py", line 53, in get_object
    obj = queryset.get()
  File "C:\Program Files\Python\Python310\lib\site-packages\django\db\models\query.py", line 492, in get
    num = len(clone)
  File "C:\Program Files\Python\Python310\lib\site-packages\django\db\models\query.py", line 302, in __len__
    self._fetch_all()
  File "C:\Program Files\Python\Python310\lib\site-packages\django\db\models\query.py", line 1507, in _fetch_all
    self._result_cache = list(self._iterable_class(self))
  File "C:\Program Files\Python\Python310\lib\site-packages\django\db\models\query.py", line 57, in __iter__
    results = compiler.execute_sql(
  File "C:\Program Files\Python\Python310\lib\site-packages\django\db\models\sql\compiler.py", line 1361, in execute_sql
    cursor.execute(sql, params)
  File "C:\Program Files\Python\Python310\lib\site-packages\django\db\backends\utils.py", line 103, in execute
    return super().execute(sql, params)
  File "C:\Program Files\Python\Python310\lib\site-packages\django\db\backends\utils.py", line 67, in execute
    return self._execute_with_wrappers(
  File "C:\Program Files\Python\Python310\lib\site-packages\django\db\backends\utils.py", line 80, in _execute_with_wrappers
    return executor(sql, params, many, context)
  File "C:\Program Files\Python\Python310\lib\site-packages\django\db\backends\utils.py", line 84, in _execute
    with self.db.wrap_database_errors:
  File "C:\Program Files\Python\Python310\lib\site-packages\django\db\utils.py", line 91, in __exit__
    raise dj_exc_value.with_traceback(traceback) from exc_value
  File "C:\Program Files\Python\Python310\lib\site-packages\django\db\backends\utils.py", line 89, in _execute
    return self.cursor.execute(sql, params)
  File "C:\Program Files\Python\Python310\lib\site-packages\django\db\backends\sqlite3\base.py", line 477, in execute
    return Database.Cursor.execute(self, query, params)
django.db.utils.OperationalError: no such column: news_post.title_en_us
ERROR 2022-07-13 20:34:46,103 "GET /news/12 HTTP/1.1" 500 156866 C:\Program Files\Python\Python310\lib\site-packages\django\core\servers\basehttp.py None
ERROR 2022-07-13 20:34:58,141 Internal Server Error: /news/ C:\Program Files\Python\Python310\lib\site-packages\django\utils\log.py (<class 'django.db.utils.OperationalError'>, OperationalError('no such column: news_post.title_en_us'), <traceback object at 0x00000263CB35CF80>)
Traceback (most recent call last):
  File "C:\Program Files\Python\Python310\lib\site-packages\django\db\backends\utils.py", line 89, in _execute
    return self.cursor.execute(sql, params)
  File "C:\Program Files\Python\Python310\lib\site-packages\django\db\backends\sqlite3\base.py", line 477, in execute
    return Database.Cursor.execute(self, query, params)
sqlite3.OperationalError: no such column: news_post.title_en_us

The above exception was the direct cause of the following exception:

Traceback (most recent call last):
  File "C:\Program Files\Python\Python310\lib\site-packages\django\core\handlers\exception.py", line 55, in inner
    response = get_response(request)
  File "C:\Program Files\Python\Python310\lib\site-packages\django\core\handlers\base.py", line 220, in _get_response
    response = response.render()
  File "C:\Program Files\Python\Python310\lib\site-packages\django\template\response.py", line 114, in render
    self.content = self.rendered_content
  File "C:\Program Files\Python\Python310\lib\site-packages\django\template\response.py", line 92, in rendered_content
    return template.render(context, self._request)
  File "C:\Program Files\Python\Python310\lib\site-packages\django\template\backends\django.py", line 62, in render
    return self.template.render(context)
  File "C:\Program Files\Python\Python310\lib\site-packages\django\template\base.py", line 175, in render
    return self._render(context)
  File "C:\Program Files\Python\Python310\lib\site-packages\django\template\base.py", line 167, in _render
    return self.nodelist.render(context)
  File "C:\Program Files\Python\Python310\lib\site-packages\django\template\base.py", line 1000, in render
    return SafeString("".join([node.render_annotated(context) for node in self]))
  File "C:\Program Files\Python\Python310\lib\site-packages\django\template\base.py", line 1000, in <listcomp>
    return SafeString("".join([node.render_annotated(context) for node in self]))
  File "C:\Program Files\Python\Python310\lib\site-packages\django\template\base.py", line 958, in render_annotated
    return self.render(context)
  File "C:\Program Files\Python\Python310\lib\site-packages\django\template\loader_tags.py", line 157, in render
    return compiled_parent._render(context)
  File "C:\Program Files\Python\Python310\lib\site-packages\django\template\base.py", line 167, in _render
    return self.nodelist.render(context)
  File "C:\Program Files\Python\Python310\lib\site-packages\django\template\base.py", line 1000, in render
    return SafeString("".join([node.render_annotated(context) for node in self]))
  File "C:\Program Files\Python\Python310\lib\site-packages\django\template\base.py", line 1000, in <listcomp>
    return SafeString("".join([node.render_annotated(context) for node in self]))
  File "C:\Program Files\Python\Python310\lib\site-packages\django\template\base.py", line 958, in render_annotated
    return self.render(context)
  File "C:\Program Files\Python\Python310\lib\site-packages\django\template\loader_tags.py", line 63, in render
    result = block.nodelist.render(context)
  File "C:\Program Files\Python\Python310\lib\site-packages\django\template\base.py", line 1000, in render
    return SafeString("".join([node.render_annotated(context) for node in self]))
  File "C:\Program Files\Python\Python310\lib\site-packages\django\template\base.py", line 1000, in <listcomp>
    return SafeString("".join([node.render_annotated(context) for node in self]))
  File "C:\Program Files\Python\Python310\lib\site-packages\django\template\base.py", line 958, in render_annotated
    return self.render(context)
  File "C:\Program Files\Python\Python310\lib\site-packages\django\template\defaulttags.py", line 321, in render
    if match:
  File "C:\Program Files\Python\Python310\lib\site-packages\django\db\models\query.py", line 324, in __bool__
    self._fetch_all()
  File "C:\Program Files\Python\Python310\lib\site-packages\django\db\models\query.py", line 1507, in _fetch_all
    self._result_cache = list(self._iterable_class(self))
  File "C:\Program Files\Python\Python310\lib\site-packages\django\db\models\query.py", line 57, in __iter__
    results = compiler.execute_sql(
  File "C:\Program Files\Python\Python310\lib\site-packages\django\db\models\sql\compiler.py", line 1361, in execute_sql
    cursor.execute(sql, params)
  File "C:\Program Files\Python\Python310\lib\site-packages\django\db\backends\utils.py", line 103, in execute
    return super().execute(sql, params)
  File "C:\Program Files\Python\Python310\lib\site-packages\django\db\backends\utils.py", line 67, in execute
    return self._execute_with_wrappers(
  File "C:\Program Files\Python\Python310\lib\site-packages\django\db\backends\utils.py", line 80, in _execute_with_wrappers
    return executor(sql, params, many, context)
  File "C:\Program Files\Python\Python310\lib\site-packages\django\db\backends\utils.py", line 84, in _execute
    with self.db.wrap_database_errors:
  File "C:\Program Files\Python\Python310\lib\site-packages\django\db\utils.py", line 91, in __exit__
    raise dj_exc_value.with_traceback(traceback) from exc_value
  File "C:\Program Files\Python\Python310\lib\site-packages\django\db\backends\utils.py", line 89, in _execute
    return self.cursor.execute(sql, params)
  File "C:\Program Files\Python\Python310\lib\site-packages\django\db\backends\sqlite3\base.py", line 477, in execute
    return Database.Cursor.execute(self, query, params)
django.db.utils.OperationalError: no such column: news_post.title_en_us
ERROR 2022-07-13 20:34:58,143 "GET /news/ HTTP/1.1" 500 208522 C:\Program Files\Python\Python310\lib\site-packages\django\core\servers\basehttp.py None
